2025-05-03 21:25:11 +0000 - dagster - DEBUG - etl_pipeline_job - ce550104-24e8-4d5a-8541-282d25bfb91a - 2791 - LOGS_CAPTURED - Started capturing logs in process (pid: 2791).
2025-05-03 21:25:11 +0000 - dagster - DEBUG - etl_pipeline_job - ce550104-24e8-4d5a-8541-282d25bfb91a - 2791 - extract_data_op - STEP_START - Started execution of step "extract_data_op".
2025-05-03 21:25:12 +0000 - dagster - DEBUG - etl_pipeline_job - ce550104-24e8-4d5a-8541-282d25bfb91a - extract_data_op - Loading file from: /opt/dagster/app/dagster_home/storage/storage/ce550104-24e8-4d5a-8541-282d25bfb91a/get_start_datetime/result using PickledObjectFilesystemIOManager...
2025-05-03 21:25:12 +0000 - dagster - DEBUG - etl_pipeline_job - ce550104-24e8-4d5a-8541-282d25bfb91a - 2791 - extract_data_op - LOADED_INPUT - Loaded input "start_date" using input manager "io_manager", from output "result" of step "get_start_datetime"
2025-05-03 21:25:12 +0000 - dagster - DEBUG - etl_pipeline_job - ce550104-24e8-4d5a-8541-282d25bfb91a - extract_data_op - Loading file from: /opt/dagster/app/dagster_home/storage/storage/ce550104-24e8-4d5a-8541-282d25bfb91a/get_end_datetime/result using PickledObjectFilesystemIOManager...
2025-05-03 21:25:12 +0000 - dagster - DEBUG - etl_pipeline_job - ce550104-24e8-4d5a-8541-282d25bfb91a - 2791 - extract_data_op - LOADED_INPUT - Loaded input "end_date" using input manager "io_manager", from output "result" of step "get_end_datetime"
2025-05-03 21:25:12 +0000 - dagster - DEBUG - etl_pipeline_job - ce550104-24e8-4d5a-8541-282d25bfb91a - 2791 - extract_data_op - STEP_INPUT - Got input "start_date" of type "Any". (Type check passed).
2025-05-03 21:25:12 +0000 - dagster - DEBUG - etl_pipeline_job - ce550104-24e8-4d5a-8541-282d25bfb91a - 2791 - extract_data_op - STEP_INPUT - Got input "end_date" of type "Any". (Type check passed).
HTTP error fetching data from API: Client error '404 NOT FOUND' for url 'http://api:8000/data?start_date=2025-05-02T00%3A00%3A00&end_date=2025-05-02T23%3A59%3A59.999999&columns=wind_speed%2Cpower'
For more information check: https://developer.mozilla.org/en-US/docs/Web/HTTP/Status/404
2025-05-03 21:25:12 +0000 - dagster - ERROR - etl_pipeline_job - ce550104-24e8-4d5a-8541-282d25bfb91a - 2791 - extract_data_op - STEP_FAILURE - Execution of step "extract_data_op" failed.

dagster._core.errors.DagsterExecutionStepExecutionError: Error occurred while executing op "extract_data_op"::

httpx.HTTPStatusError: Client error '404 NOT FOUND' for url 'http://api:8000/data?start_date=2025-05-02T00%3A00%3A00&end_date=2025-05-02T23%3A59%3A59.999999&columns=wind_speed%2Cpower'
For more information check: https://developer.mozilla.org/en-US/docs/Web/HTTP/Status/404

Stack Trace:
  File "/usr/local/lib/python3.9/site-packages/dagster/_core/execution/plan/utils.py", line 56, in op_execution_error_boundary
    yield
  File "/usr/local/lib/python3.9/site-packages/dagster/_utils/__init__.py", line 392, in iterate_with_context
    next_output = next(iterator)
  File "/usr/local/lib/python3.9/site-packages/dagster/_core/execution/plan/compute_generator.py", line 129, in _coerce_op_compute_fn_to_iterator
    result = invoke_compute_fn(
  File "/usr/local/lib/python3.9/site-packages/dagster/_core/execution/plan/compute_generator.py", line 117, in invoke_compute_fn
    return fn(context, **args_to_pass) if context_arg_provided else fn(**args_to_pass)
  File "/opt/dagster/app/dagster_defs/__init__.py", line 130, in extract_data_op
    df = fetch_data_from_api(start_date, end_date, columns=["wind_speed", "power"])
  File "/opt/dagster/app/etl/transform.py", line 44, in fetch_data_from_api
    response.raise_for_status()
  File "/usr/local/lib/python3.9/site-packages/httpx/_models.py", line 829, in raise_for_status
    raise HTTPStatusError(message, request=request, response=self)

